<?xml version="1.0"?>
<robot name="valve">
  <link name="valve_base_left_support">
    <visual>
      <geometry>
        <box size="0.1 0.1 2.0"/>
      </geometry>
      <origin rpy="0 0 0" xyz="0 0 0"/>
      <material name="blueish">
	<color rgba="0.1 0.1 0.1 0.5"/>
      </material>
    </visual>
    <collision>
      <geometry>
        <box size="0.1 0.1 2.0"/>
      </geometry>
    </collision>
    <inertial>
      <origin xyz="0 0 0"/>
      <mass value="10"/>
      <inertia ixx="1.0" ixy="0.0" ixz="0.0" iyy="1.0" iyz="0.0" izz="1.0"/>
    </inertial>
  </link>

  <link name="valve_base_right_support">
    <visual>
      <geometry>
        <box size="0.1 0.1 2.0"/>
      </geometry>
      <origin rpy="0 0 0" xyz="0 0 0"/>
      <material name="blueish">
	<color rgba="0.1 0.1 0.1 0.5"/>
      </material>
    </visual>
    <collision>
      <geometry>
        <box size="0.1 0.1 2.0"/>
      </geometry>
    </collision>
    <inertial>
      <origin xyz="0 0 0"/>
      <mass value="10"/>
      <inertia ixx="1.0" ixy="0.0" ixz="0.0" iyy="1.0" iyz="0.0" izz="1.0"/>
    </inertial>
  </link>

  <link name="valve_base_middle_bridge">
    <visual>
      <geometry>
	<cylinder length="2.0" radius="0.05"/>
      </geometry>
      <origin rpy="1.57075 0 0" xyz="0 0 0"/>
      <material name="whiteish">
	<color rgba="1.0 1.0 1.0 1.0"/>
      </material>
    </visual>
    <collision>
      <geometry>
	<cylinder length="2.0" radius="0.05"/>
      </geometry>
      <origin rpy="1.57075 0 0" xyz="0 0 0"/>
    </collision>
    <inertial>
      <origin xyz="0 0 0"/>
      <mass value="0.1"/>
      <inertia ixx="1.0" ixy="0.0" ixz="0.0" iyy="1.0" iyz="0.0" izz="1.0"/>
    </inertial>
  </link>

  <link name="handle">
    <visual>
      <geometry>
	<mesh filename="package://wpi_drc_sim/meshes/valve_models/logitech_driving_force_pro_wheel.dae" scale="0.05 0.05 0.05"/>
      </geometry>
    </visual>
    <collision>
      <geometry>
        <mesh filename="package://wpi_drc_sim/meshes/valve_models/logitech_driving_force_pro_wheel.stl" scale="0.05 0.05 0.05"/>
      </geometry>
    </collision>
    <inertial>
      <origin xyz="0 0 0"/>
      <mass value="0.1"/>
      <inertia ixx="1.0" ixy="0.0" ixz="0.0" iyy="1.0" iyz="0.0" izz="1.0"/>
    </inertial>
  </link>
  
  <link name="rod">
    <visual>
      <geometry>
	<cylinder length="0.2" radius="0.005"/>
      </geometry>
      <origin rpy="0 1.57075 0" xyz="0.1 0 0"/>
      <material name="whiteish">
	<color rgba="1.0 1.0 1.0 1.0"/>
      </material>
    </visual>
    <collision>
      <geometry>
	<cylinder length="0.1" radius="0.005"/>
      </geometry>
      <origin rpy="0 1.57075 0" xyz="0.1 0 0"/>
    </collision>
    <inertial>
      <origin xyz="0 0 0"/>
      <mass value="0.1"/>
      <inertia ixx="1.0" ixy="0.0" ixz="0.0" iyy="1.0" iyz="0.0" izz="1.0"/>
    </inertial>
  </link>

  <joint name="left_support" type="fixed">
    <parent link="valve_base_left_support"/>
    <child link="valve_base_middle_bridge"/>
    <origin xyz="0 1 0"/>
  </joint>
  
  <joint name="right_support" type="fixed">
    <parent link="valve_base_middle_bridge"/>
    <child link="valve_base_right_support"/>
    <origin xyz="0 1 0"/>
  </joint>

  <joint name="body_to_rod" type="fixed">
    <parent link="valve_base_middle_bridge"/>
    <child link="rod"/>
    <origin xyz="0 0 0" rpy="0 0 0"/>
  </joint>

  <joint name="rod_to_handle" type="continuous">
    <parent link="rod"/>
    <child link="handle"/>
    <axis xyz="1 0 0"/>
    <origin xyz="0.2 0 0"/>
  </joint>

  <gazebo reference="valve_base_middle_bridge">
    <material>Gazebo/White</material>
  </gazebo>
</robot>